Workbook

Sheet Fixed Costs
A1: Seek — Fixed Monthly Costs
A2: Last updated: 2026-05-01. Blue cells are editable inputs.
A4: Item | B4: Annual ($) | C4: Monthly ($) | D4: Notes
A5: Apple Developer Program | B5: 99 | C5: =B5/12 | D5: Required for App Store distribution + future APNs key
A6: Domain (askseekpray.app) | B6: 20 | C6: =B6/12 | D6: GoDaddy renewal — .app TLD
A7: GitHub | B7: 0 | C7: =B7/12 | D7: Free — public repo at github.com/garvonious-ui/Seek
A8: Vercel (landing page) | B8: 0 | C8: =B8/12 | D8: Free Hobby tier — well within bandwidth limits
A9: Supabase (base) | B9: 0 | C9: =B9/12 | D9: See "Variable Cost Model" — Free until ~8K MAU, $25/mo Pro after
A10: Anthropic API (base) | B10: 0 | C10: =B10/12 | D10: See "Variable Cost Model" — pure usage-based, no minimum
A11: Stripe (base) | B11: 0 | C11: =B11/12 | D11: See "Variable Cost Model" — 2.9% + $0.30 per donation, no monthly
A12: Resend (transactional email) | B12: 0 | C12: =B12/12 | D12: Free tier covers 3K emails/mo — enough for years
A13: Google Workspace (email) | B13: 192 | C13: =B13/12 | D13: $16/mo — hello@askseekpray.app + admin
A15: Total Fixed | B15: =SUM(B5:B13) | C15: =SUM(C5:C13)

Sheet Variable Cost Model
A1: Seek — Variable Cost Model (per month)
A2: Blue = inputs you can tweak. Black = formulas. Yellow = key assumption — revisit when real data lands.
A4: USAGE INPUTS
A5: Monthly Active Users (MAU) | B5: 1000 | C5: Tweak this to model different scales
A6: DAU / MAU ratio | B6: 0.3 | C6: Industry: 20-40% for engaged faith / wellness apps
A7: Avg chats per DAU per day | B7: 1.5 | C7: Most users send <2; power users hit 50/day cap
A8: Daily verse views per MAU per month | B8: 18 | C8: Avg user opens app ~18 days/mo and views daily verse
A10: DERIVED USAGE
A11: DAU | B11: =B5*B6
A12: Total chats per month | B12: =B11*B7*30 | C12: DAU × chats/day × 30
A13: Edge Function invocations / month | B13: =B12+(B5*B8) | C13: chats + daily-verse views
A15: ANTHROPIC CLAUDE API (claude-sonnet-4-6)
A16: System prompt tokens (per chat) | B16: 1800 | C16: Approximate; system prompt in chat/index.ts
A17: Avg fresh input tokens per chat | B17: 750 | C17: User message + conversation history
A18: Avg output tokens per chat | B18: 2000 | C18: Cap is 3000; full responses run 1500-2500
A19: Input price per 1M tokens | B19: 3 | C19: Sonnet 4.6 standard input pricing
A20: Output price per 1M tokens | B20: 15 | C20: Sonnet 4.6 standard output pricing
A21: Cached input price per 1M tokens | B21: 0.3 | C21: 10% of input — when prompt caching is enabled
A22: Prompt caching enabled? (1=yes, 0=no) | B22: 0 | C22: Set to 1 if caching is wired in chat Edge Function
A24: Per-chat input cost | B24: =IF(B22=1, (B16*B21+B17*B19)/1000000, (B16+B17)*B19/1000000) | C24: Caching cuts system-prompt cost ~10x
A25: Per-chat output cost | B25: =B18*B20/1000000
A26: Total cost per chat | B26: =B24+B25
A27: Monthly Claude cost | B27: =B26*B12
A29: SUPABASE
A30: Free tier MAU cap | B30: 50000 | C30: 50K MAU on Free
A31: Free tier EF invocations cap | B31: 500000 | C31: 500K Edge Function invocations / mo on Free
A32: Pro tier base price ($/mo) | B32: 25 | C32: $25/mo flat
A33: Pro tier MAU included | B33: 100000 | C33: 100K MAU included
A34: Pro tier MAU overage rate | B34: 0.00325 | C34: $0.00325 per MAU above 100K
A35: Pro tier EF included | B35: 2000000 | C35: 2M EF invocations included
A36: Pro tier EF overage per 1M | B36: 2 | C36: $2 per 1M extra Edge Function invocations
A38: Tier required | B38: =IF(AND(B5<=B30, B13<=B31), "Free", "Pro") | C38: Auto-flips when EF cap or MAU cap is hit
A39: Supabase monthly cost | B39: =IF(B38="Free", 0, B32 + MAX(0, B5-B33)*B34 + MAX(0, (B13-B35)/1000000)*B36)
A41: DONATIONS & STRIPE FEES
A42: % of MAU who donate / month | B42: 0.005 | C42: 0.5% is realistic with no nag; nudge card may push higher
A43: Avg donation amount ($) | B43: 25 | C43: Weighted by preset distribution ($10/$25/$50/$100/$250/$500)
A44: Stripe fee % | B44: 0.029 | C44: 2.9% standard for cards
A45: Stripe fixed fee per txn ($) | B45: 0.3 | C45: $0.30 per transaction
A47: Donating users / month | B47: =B5*B42
A48: Gross donation revenue | B48: =B47*B43
...

Sheet Scenarios
A1: Seek — Cost Scenarios at Different Scales
A2: All assumptions pull from 'Variable Cost Model' (green text). Edit MAU per column in row 5.
A4: Scenario | B4: Pre-launch | C4: Early traction | D4: Growing | E4: Successful | F4: Notes
A5: Monthly Active Users | B5: 100 | C5: 1000 | D5: 10000 | E5: 50000
A7: USAGE
A8: DAU | B8: =ROUND(B5*'Variable Cost Model'!$B$6,0) | C8: =ROUND(C5*'Variable Cost Model'!$B$6,0) | D8: =ROUND(D5*'Variable Cost Model'!$B$6,0) | E8: =ROUND(E5*'Variable Cost Model'!$B$6,0) | F8: MAU × DAU/MAU ratio (from Variable Cost Model)
A9: Chats per month | B9: =ROUND(B8*'Variable Cost Model'!$B$7*30,0) | C9: =ROUND(C8*'Variable Cost Model'!$B$7*30,0) | D9: =ROUND(D8*'Variable Cost Model'!$B$7*30,0) | E9: =ROUND(E8*'Variable Cost Model'!$B$7*30,0) | F9: DAU × chats/day × 30
A10: Edge Function invocations | B10: =ROUND(B9 + B5*'Variable Cost Model'!$B$8, 0) | C10: =ROUND(C9 + C5*'Variable Cost Model'!$B$8, 0) | D10: =ROUND(D9 + D5*'Variable Cost Model'!$B$8, 0) | E10: =ROUND(E9 + E5*'Variable Cost Model'!$B$8, 0) | F10: chats + daily-verse views
A12: MONTHLY COSTS
A13: Fixed costs | B13: ='Fixed Costs'!$C$15 | C13: ='Fixed Costs'!$C$15 | D13: ='Fixed Costs'!$C$15 | E13: ='Fixed Costs'!$C$15 | F13: Apple Dev + domain
A14: Anthropic Claude API | B14: =B9 * 'Variable Cost Model'!$B$26 | C14: =C9 * 'Variable Cost Model'!$B$26 | D14: =D9 * 'Variable Cost Model'!$B$26 | E14: =E9 * 'Variable Cost Model'!$B$26 | F14: chats × cost-per-chat
A15: Supabase | B15: =IF(AND(B5<='Variable Cost Model'!$B$30, B10<='Variable Cost Model'!$B$31), 0, 'Variable Cost Model'!$B$32 + MAX(0, B5-'Variable Cost Model'!$B$33)*'Variable Cost Model'!$B$34 + MAX(0, (B10-'Variable Cost Model'!$B$35)/1000000)*'Variable Cost Model'!$B$36) | C15: =IF(AND(C5<='Variable Cost Model'!$B$30, C10<='Variable Cost Model'!$B$31), 0, 'Variable Cost Model'!$B$32 + MAX(0, C5-'Variable Cost Model'!$B$33)*'Variable Cost Model'!$B$34 + MAX(0, (C10-'Variable Cost Model'!$B$35)/1000000)*'Variable Cost Model'!$B$36) | D15: =IF(AND(D5<='Variable Cost Model'!$B$30, D10<='Variable Cost Model'!$B$31), 0, 'Variable Cost Model'!$B$32 + MAX(0, D5-'Variable Cost Model'!$B$33)*'Variable Cost Model'!$B$34 + MAX(0, (D10-'Variable Cost Model'!$B$35)/1000000)*'Variable Cost Model'!$B$36) | E15: =IF(AND(E5<='Variable Cost Model'!$B$30, E10<='Variable Cost Model'!$B$31), 0, 'Variable Cost Model'!$B$32 + MAX(0, E5-'Variable Cost Model'!$B$33)*'Variable Cost Model'!$B$34 + MAX(0, (E10-'Variable Cost Model'!$B$35)/1000000)*'Variable Cost Model'!$B$36) | F15: Free until MAU or EF cap hit; then $25 + overage
A16: Stripe fees | B16: =(B5*'Variable Cost Model'!$B$42*'Variable Cost Model'!$B$43)*'Variable Cost Model'!$B$44 + (B5*'Variable Cost Model'!$B$42)*'Variable Cost Model'!$B$45 | C16: =(C5*'Variable Cost Model'!$B$42*'Variable Cost Model'!$B$43)*'Variable Cost Model'!$B$44 + (C5*'Variable Cost Model'!$B$42)*'Variable Cost Model'!$B$45 | D16: =(D5*'Variable Cost Model'!$B$42*'Variable Cost Model'!$B$43)*'Variable Cost Model'!$B$44 + (D5*'Variable Cost Model'!$B$42)*'Variable Cost Model'!$B$45 | E16: =(E5*'Variable Cost Model'!$B$42*'Variable Cost Model'!$B$43)*'Variable Cost Model'!$B$44 + (E5*'Variable Cost Model'!$B$42)*'Variable Cost Model'!$B$45 | F16: 2.9% × gross + $0.30 × txns
A17: TOTAL MONTHLY COST | B17: =SUM(B13:B16) | C17: =SUM(C13:C16) | D17: =SUM(D13:D16) | E17: =SUM(E13:E16)
A19: DONATION REVENUE
A20: Donating users | B20: =ROUND(B5*'Variable Cost Model'!$B$42,0) | C20: =ROUND(C5*'Variable Cost Model'!$B$42,0) | D20: =ROUND(D5*'Variable Cost Model'!$B$42,0) | E20: =ROUND(E5*'Variable Cost Model'!$B$42,0)
A21: Gross donations | B21: =B20*'Variable Cost Model'!$B$43 | C21: =C20*'Variable Cost Model'!$B$43 | D21: =D20*'Variable Cost Model'!$B$43 | E21: =E20*'Variable Cost Model'!$B$43
A22: Net donations (after Stripe) | B22: =B21-B16 | C22: =C21-C16 | D22: =D21-D16 | E22: =E21-E16
A24: NET POSITION
A25: NET MONTHLY (cost − net donations) | B25: =B17-B22 | C25: =C17-C22 | D25: =D17-D22 | E25: =E17-E22
A26: Cost per MAU | B26: =IF(B5>0, B17/B5, 0) | C26: =IF(C5>0, C17/C5, 0) | D26: =IF(D5>0, D17/D5, 0) | E26: =IF(E5>0, E17/E5, 0)
A27: Annualized total cost | B27: =B17*12 | C27: =C17*12 | D27: =D17*12 | E27: =E17*12
A28: Annualized net | B28: =B25*12 | C28: =C25*12 | D28: =D25*12 | E28: =E25*12
A30: QUICK READ
A31: → Anthropic API is the dominant variable cost. Claude pricing & token volume drive everything.
A32: → Supabase Free covers small scale; Pro ($25/mo) kicks in around 8-10K MAU based on EF invocations.
A33: → Donations only need to convert ~0.3% of MAU @ $25 avg to fully cover Claude costs at most scales.
A34: → Enabling prompt caching (set B22=1 in 'Variable Cost Model') trims ~10% off per-chat cost.
